Workbook

Sheet BP
A1: ตารางเกณฑ์ดัชนีคุณภาพอากาศของประเทศไทย (TH AQI) — PM2.5 เฉลี่ย 24 ชม.
A2: ที่มา: ประกาศกรมควบคุมมลพิษ เรื่อง ดัชนีคุณภาพอากาศของประเทศไทย พ.ศ. 2566 (บังคับใช้ 1 มิ.ย. 2566) / air4thai.pcd.go.th
A4: C_low (มคก./ลบ.ม.) | B4: C_high (มคก./ลบ.ม.) | C4: I_low | D4: I_high | E4: AQI เริ่มช่วง | F4: ระดับคุณภาพอากาศ | G4: สี
A5: 0 | B5: 15 | C5: 0 | D5: 25 | E5: 0 | F5: ดีมาก | G5: ฟ้า
A6: 15.1 | B6: 25 | C6: 26 | D6: 50 | E6: 26 | F6: ดี | G6: เขียว
A7: 25.1 | B7: 37.5 | C7: 51 | D7: 100 | E7: 51 | F7: ปานกลาง | G7: เหลือง
A8: 37.6 | B8: 75 | C8: 101 | D8: 200 | E8: 101 | F8: เริ่มมีผลกระทบต่อสุขภาพ | G8: ส้ม
A9: 75.1 | B9: 500 | C9: 201 | D9: 500 | E9: 201 | F9: มีผลกระทบต่อสุขภาพ | G9: แดง
A11: สูตร: AQI = ((I_high − I_low) / (C_high − C_low)) × (C − C_low) + I_low แล้วปัดเป็นจำนวนเต็ม
A12: C = ความเข้มข้น PM2.5 ที่ตรวจวัดได้ (เฉลี่ย 24 ชม.) | เมื่อมีมลพิษหลายชนิด AQI = ค่าสูงสุดของดัชนีย่อยทุกชนิด
A14: หมายเหตุข้อมูล: แถวที่มีวันที่ 2021-06-30 ซ้ำกัน 2 แถวในไฟล์ต้นฉบับ และไม่มีวันที่ 2021-06-29 จึงถือว่าแถวแรกคือ 2021-06-29
A15: ข้อมูลสถานี 44T ต.หาดใหญ่ อ.หาดใหญ่ จ.สงขลา (เทศบาลนครหาดใหญ่) มีวันที่ไม่มีค่าตรวจวัด 22 วัน ซึ่งถูกเว้นว่างไว้

Sheet Data
A1: วันที่ | B1: PM2.5 (มคก./ลบ.ม.) | C1: AQI | D1: ระดับคุณภาพอากาศ | E1: ปี | F1: เดือน | G1: ลมสูงสุด (km/h) | H1: ลมกระโชก (km/h) | I1: ทิศลม (°) | J1: ฝน model (มม.) | K1: ปริมาณน้ำฝน (มม.) | L1: ประเภทวัน
A2: 44197 | B2: 20 | C2: =IF(NOT(ISNUMBER(B2)),"",ROUND((INDEX(BP!$D$5:$D$9,MATCH(B2,BP!$A$5:$A$9,1))-INDEX(BP!$C$5:$C$9,MATCH(B2,BP!$A$5:$A$9,1)))/(INDEX(BP!$B$5:$B$9,MATCH(B2,BP!$A$5:$A$9,1))-INDEX(BP!$A$5:$A$9,MATCH(B2,BP!$A$5:$A$9,1)))*(B2-INDEX(BP!$A$5:$A$9,MATCH(B2,BP!$A$5:$A$9,1)))+INDEX(BP!$C$5:$C$9,MATCH(B2,BP!$A$5:$A$9,1)),0)) -> 38 | D2: =IF(NOT(ISNUMBER(C2)),"",INDEX(BP!$F$5:$F$9,MATCH(C2,BP!$E$5:$E$9,1))) -> ดี | E2: =YEAR(A2) -> 2021 | F2: =MONTH(A2) -> 1 | G2: 25.8 | H2: 52.9 | I2: 65 | J2: 8 | K2: 8.2 | L2: วันหยุดราชการ/นักขัตฤกษ์
A3: 44198 | B3: 16 | C3: =IF(NOT(ISNUMBER(B3)),"",ROUND((INDEX(BP!$D$5:$D$9,MATCH(B3,BP!$A$5:$A$9,1))-INDEX(BP!$C$5:$C$9,MATCH(B3,BP!$A$5:$A$9,1)))/(INDEX(BP!$B$5:$B$9,MATCH(B3,BP!$A$5:$A$9,1))-INDEX(BP!$A$5:$A$9,MATCH(B3,BP!$A$5:$A$9,1)))*(B3-INDEX(BP!$A$5:$A$9,MATCH(B3,BP!$A$5:$A$9,1)))+INDEX(BP!$C$5:$C$9,MATCH(B3,BP!$A$5:$A$9,1)),0)) -> 28 | D3: =IF(NOT(ISNUMBER(C3)),"",INDEX(BP!$F$5:$F$9,MATCH(C3,BP!$E$5:$E$9,1))) -> ดี | E3: =YEAR(A3) -> 2021 | F3: =MONTH(A3) -> 1 | G3: 20.7 | H3: 46.1 | I3: 57 | J3: 5 | K3: 30 | L3: วันหยุดสุดสัปดาห์
A4: 44199 | B4: 15 | C4: =IF(NOT(ISNUMBER(B4)),"",ROUND((INDEX(BP!$D$5:$D$9,MATCH(B4,BP!$A$5:$A$9,1))-INDEX(BP!$C$5:$C$9,MATCH(B4,BP!$A$5:$A$9,1)))/(INDEX(BP!$B$5:$B$9,MATCH(B4,BP!$A$5:$A$9,1))-INDEX(BP!$A$5:$A$9,MATCH(B4,BP!$A$5:$A$9,1)))*(B4-INDEX(BP!$A$5:$A$9,MATCH(B4,BP!$A$5:$A$9,1)))+INDEX(BP!$C$5:$C$9,MATCH(B4,BP!$A$5:$A$9,1)),0)) -> 25 | D4: =IF(NOT(ISNUMBER(C4)),"",INDEX(BP!$F$5:$F$9,MATCH(C4,BP!$E$5:$E$9,1))) -> ดีมาก | E4: =YEAR(A4) -> 2021 | F4: =MONTH(A4) -> 1 | G4: 23.8 | H4: 49.7 | I4: 58 | J4: 6 | K4: 31.4 | L4: วันหยุดสุดสัปดาห์
A5: 44200 | B5: 12 | C5: =IF(NOT(ISNUMBER(B5)),"",ROUND((INDEX(BP!$D$5:$D$9,MATCH(B5,BP!$A$5:$A$9,1))-INDEX(BP!$C$5:$C$9,MATCH(B5,BP!$A$5:$A$9,1)))/(INDEX(BP!$B$5:$B$9,MATCH(B5,BP!$A$5:$A$9,1))-INDEX(BP!$A$5:$A$9,MATCH(B5,BP!$A$5:$A$9,1)))*(B5-INDEX(BP!$A$5:$A$9,MATCH(B5,BP!$A$5:$A$9,1)))+INDEX(BP!$C$5:$C$9,MATCH(B5,BP!$A$5:$A$9,1)),0)) -> 20 | D5: =IF(NOT(ISNUMBER(C5)),"",INDEX(BP!$F$5:$F$9,MATCH(C5,BP!$E$5:$E$9,1))) -> ดีมาก | E5: =YEAR(A5) -> 2021 | F5: =MONTH(A5) -> 1 | G5: 25.2 | H5: 55.8 | I5: 84 | J5: 13.9 | K5: 7.8 | L5: วันทำงานปกติ
A6: 44201 | B6: 14 | C6: =IF(NOT(ISNUMBER(B6)),"",ROUND((INDEX(BP!$D$5:$D$9,MATCH(B6,BP!$A$5:$A$9,1))-INDEX(BP!$C$5:$C$9,MATCH(B6,BP!$A$5:$A$9,1)))/(INDEX(BP!$B$5:$B$9,MATCH(B6,BP!$A$5:$A$9,1))-INDEX(BP!$A$5:$A$9,MATCH(B6,BP!$A$5:$A$9,1)))*(B6-INDEX(BP!$A$5:$A$9,MATCH(B6,BP!$A$5:$A$9,1)))+INDEX(BP!$C$5:$C$9,MATCH(B6,BP!$A$5:$A$9,1)),0)) -> 23 | D6: =IF(NOT(ISNUMBER(C6)),"",INDEX(BP!$F$5:$F$9,MATCH(C6,BP!$E$5:$E$9,1))) -> ดีมาก | E6: =YEAR(A6) -> 2021 | F6: =MONTH(A6) -> 1 | G6: 17.3 | H6: 41.4 | I6: 54 | J6: 18.3 | K6: 43.6 | L6: วันทำงานปกติ
A7: 44202 | B7: 11 | C7: =IF(NOT(ISNUMBER(B7)),"",ROUND((INDEX(BP!$D$5:$D$9,MATCH(B7,BP!$A$5:$A$9,1))-INDEX(BP!$C$5:$C$9,MATCH(B7,BP!$A$5:$A$9,1)))/(INDEX(BP!$B$5:$B$9,MATCH(B7,BP!$A$5:$A$9,1))-INDEX(BP!$A$5:$A$9,MATCH(B7,BP!$A$5:$A$9,1)))*(B7-INDEX(BP!$A$5:$A$9,MATCH(B7,BP!$A$5:$A$9,1)))+INDEX(BP!$C$5:$C$9,MATCH(B7,BP!$A$5:$A$9,1)),0)) -> 18 | D7: =IF(NOT(ISNUMBER(C7)),"",INDEX(BP!$F$5:$F$9,MATCH(C7,BP!$E$5:$E$9,1))) -> ดีมาก | E7: =YEAR(A7) -> 2021 | F7: =MONTH(A7) -> 1 | G7: 20.1 | H7: 52.9 | I7: 78 | J7: 11.4 | K7: 2.2 | L7: วันทำงานปกติ
A8: 44203 | B8: 11 | C8: =IF(NOT(ISNUMBER(B8)),"",ROUND((INDEX(BP!$D$5:$D$9,MATCH(B8,BP!$A$5:$A$9,1))-INDEX(BP!$C$5:$C$9,MATCH(B8,BP!$A$5:$A$9,1)))/(INDEX(BP!$B$5:$B$9,MATCH(B8,BP!$A$5:$A$9,1))-INDEX(BP!$A$5:$A$9,MATCH(B8,BP!$A$5:$A$9,1)))*(B8-INDEX(BP!$A$5:$A$9,MATCH(B8,BP!$A$5:$A$9,1)))+INDEX(BP!$C$5:$C$9,MATCH(B8,BP!$A$5:$A$9,1)),0)) -> 18 | D8: =IF(NOT(ISNUMBER(C8)),"",INDEX(BP!$F$5:$F$9,MATCH(C8,BP!$E$5:$E$9,1))) -> ดีมาก | E8: =YEAR(A8) -> 2021 | F8: =MONTH(A8) -> 1 | G8: 20.2 | H8: 47.2 | I8: 88 | J8: 11.9 | K8: 0.2 | L8: วันทำงานปกติ
A9: 44204 | B9: 12 | C9: =IF(NOT(ISNUMBER(B9)),"",ROUND((INDEX(BP!$D$5:$D$9,MATCH(B9,BP!$A$5:$A$9,1))-INDEX(BP!$C$5:$C$9,MATCH(B9,BP!$A$5:$A$9,1)))/(INDEX(BP!$B$5:$B$9,MATCH(B9,BP!$A$5:$A$9,1))-INDEX(BP!$A$5:$A$9,MATCH(B9,BP!$A$5:$A$9,1)))*(B9-INDEX(BP!$A$5:$A$9,MATCH(B9,BP!$A$5:$A$9,1)))+INDEX(BP!$C$5:$C$9,MATCH(B9,BP!$A$5:$A$9,1)),0)) -> 20 | D9: =IF(NOT(ISNUMBER(C9)),"",INDEX(BP!$F$5:$F$9,MATCH(C9,BP!$E$5:$E$9,1))) -> ดีมาก | E9: =YEAR(A9) -> 2021 | F9: =MONTH(A9) -> 1 | G9: 26.6 | H9: 56.9 | I9: 94 | J9: 1.5 | K9: 0 | L9: วันทำงานปกติ
A10: 44205 | B10: 13 | C10: =IF(NOT(ISNUMBER(B10)),"",ROUND((INDEX(BP!$D$5:$D$9,MATCH(B10,BP!$A$5:$A$9,1))-INDEX(BP!$C$5:$C$9,MATCH(B10,BP!$A$5:$A$9,1)))/(INDEX(BP!$B$5:$B$9,MATCH(B10,BP!$A$5:$A$9,1))-INDEX(BP!$A$5:$A$9,MATCH(B10,BP!$A$5:$A$9,1)))*(B10-INDEX(BP!$A$5:$A$9,MATCH(B10,BP!$A$5:$A$9,1)))+INDEX(BP!$C$5:$C$9,MATCH(B10,BP!$A$5:$A$9,1)),0)) -> 22 | D10: =IF(NOT(ISNUMBER(C10)),"",INDEX(BP!$F$5:$F$9,MATCH(C10,BP!$E$5:$E$9,1))) -> ดีมาก | E10: =YEAR(A10) -> 2021 | F10: =MONTH(A10) -> 1 | G10: 25.6 | H10: 54.7 | I10: 95 | J10: 2.3 | K10: 0 | L10: วันหยุดสุดสัปดาห์
A11: 44206 | B11: 16 | C11: =IF(NOT(ISNUMBER(B11)),"",ROUND((INDEX(BP!$D$5:$D$9,MATCH(B11,BP!$A$5:$A$9,1))-INDEX(BP!$C$5:$C$9,MATCH(B11,BP!$A$5:$A$9,1)))/(INDEX(BP!$B$5:$B$9,MATCH(B11,BP!$A$5:$A$9,1))-INDEX(BP!$A$5:$A$9,MATCH(B11,BP!$A$5:$A$9,1)))*(B11-INDEX(BP!$A$5:$A$9,MATCH(B11,BP!$A$5:$A$9,1)))+INDEX(BP!$C$5:$C$9,MATCH(B11,BP!$A$5:$A$9,1)),0)) -> 28 | D11: =IF(NOT(ISNUMBER(C11)),"",INDEX(BP!$F$5:$F$9,MATCH(C11,BP!$E$5:$E$9,1))) -> ดี | E11: =YEAR(A11) -> 2021 | F11: =MONTH(A11) -> 1 | G11: 20.3 | H11: 43.9 | I11: 84 | J11: 8.5 | K11: 30.2 | L11: วันหยุดสุดสัปดาห์
A12: 44207 | B12: 14 | C12: =IF(NOT(ISNUMBER(B12)),"",ROUND((INDEX(BP!$D$5:$D$9,MATCH(B12,BP!$A$5:$A$9,1))-INDEX(BP!$C$5:$C$9,MATCH(B12,BP!$A$5:$A$9,1)))/(INDEX(BP!$B$5:$B$9,MATCH(B12,BP!$A$5:$A$9,1))-INDEX(BP!$A$5:$A$9,MATCH(B12,BP!$A$5:$A$9,1)))*(B12-INDEX(BP!$A$5:$A$9,MATCH(B12,BP!$A$5:$A$9,1)))+INDEX(BP!$C$5:$C$9,MATCH(B12,BP!$A$5:$A$9,1)),0)) -> 23 | D12: =IF(NOT(ISNUMBER(C12)),"",INDEX(BP!$F$5:$F$9,MATCH(C12,BP!$E$5:$E$9,1))) -> ดีมาก | E12: =YEAR(A12) -> 2021 | F12: =MONTH(A12) -> 1 | G12: 21.3 | H12: 43.9 | I12: 83 | J12: 4.4 | K12: 0.8 | L12: วันทำงานปกติ
A13: 44208 | B13: 14 | C13: =IF(NOT(ISNUMBER(B13)),"",ROUND((INDEX(BP!$D$5:$D$9,MATCH(B13,BP!$A$5:$A$9,1))-INDEX(BP!$C$5:$C$9,MATCH(B13,BP!$A$5:$A$9,1)))/(INDEX(BP!$B$5:$B$9,MATCH(B13,BP!$A$5:$A$9,1))-INDEX(BP!$A$5:$A$9,MATCH(B13,BP!$A$5:$A$9,1)))*(B13-INDEX(BP!$A$5:$A$9,MATCH(B13,BP!$A$5:$A$9,1)))+INDEX(BP!$C$5:$C$9,MATCH(B13,BP!$A$5:$A$9,1)),0)) -> 23 | D13: =IF(NOT(ISNUMBER(C13)),"",INDEX(BP!$F$5:$F$9,MATCH(C13,BP!$E$5:$E$9,1))) -> ดีมาก | E13: =YEAR(A13) -> 2021 | F13: =MONTH(A13) -> 1 | G13: 24 | H13: 50.4 | I13: 75 | J13: 5.6 | K13: 0.6 | L13: วันทำงานปกติ
... A399: 44594 | B399: 12 | C399: =IF(NOT(ISNUMBER(B399)),"",ROUND((INDEX(BP!$D$5:$D$9,MATCH(B399,BP!$A$5:$A$9,1))-INDEX(BP!$C$5:$C$9,MATCH(B399,BP!$A$5:$A$9,1)))/(INDEX(BP!$B$5:$B$9,MATCH(B399,BP!$A$5:$A$9,1))-INDEX(BP!$A$5:$A$9,MATCH(B399,BP!$A$5:$A$9,1)))*(B399-INDEX(BP!$A$5:$A$9,MATCH(B399,BP!$A$5:$A$9,1)))+INDEX(BP!$C$5:$C$9,MATCH(B399,BP!$A$5:$A$9,1)),0)) -> 20 | D399: =IF(NOT(ISNUMBER(C399)),"",INDEX(BP!$F$5:$F$9,MATCH(C399,BP!$E$5:$E$9,1))) -> ดีมาก | E399: =YEAR(A399) -> 2022 | F399: =MONTH(A399) -> 2 | G399: 22.7 | H399: 44.3 | I399: 97 | J399: 2.7 | K399: 0 | L399: วันทำงานปกติ
A400: 44595 | C400: =IF(NOT(ISNUMBER(B400)),"",ROUND((INDEX(BP!$D$5:$D$9,MATCH(B400,BP!$A$5:$A$9,1))-INDEX(BP!$C$5:$C$9,MATCH(B400,BP!$A$5:$A$9,1)))/(INDEX(BP!$B$5:$B$9,MATCH(B400,BP!$A$5:$A$9,1))-INDEX(BP!$A$5:$A$9,MATCH(B400,BP!$A$5:$A$9,1)))*(B400-INDEX(BP!$A$5:$A$9,MATCH(B400,BP!$A$5:$A$9,1)))+INDEX(BP!$C$5:$C$9,MATCH(B400,BP!$A$5:$A$9,1)),0)) | D400: =IF(NOT(ISNUMBER(C400)),"",INDEX(BP!$F$5:$F$9,MATCH(C400,BP!$E$5:$E$9,1))) | E400: =YEAR(A400) -> 2022 | F400: =MONTH(A400) -> 2 | G400: 19.8 | H400: 42.1 | I400: 92 | J400: 1.7 | K400: 0 | L400: วันทำงานปกติ
A401: 44596 | B401: 15 | C401: =IF(NOT(ISNUMBER(B401)),"",ROUND((INDEX(BP!$D$5:$D$9,MATCH(B401,BP!$A$5:$A$9,1))-INDEX(BP!$C$5:$C$9,MATCH(B401,BP!$A$5:$A$9,1)))/(INDEX(BP!$B$5:$B$9,MATCH(B401,BP!$A$5:$A$9,1))-INDEX(BP!$A$5:$A$9,MATCH(B401,BP!$A$5:$A$9,1)))*(B401-INDEX(BP!$A$5:$A$9,MATCH(B401,BP!$A$5:$A$9,1)))+INDEX(BP!$C$5:$C$9,MATCH(B401,BP!$A$5:$A$9,1)),0)) -> 25 | D401: =IF(NOT(ISNUMBER(C401)),"",INDEX(BP!$F$5:$F$9,MATCH(C401,BP!$E$5:$E$9,1))) -> ดีมาก | E401: =YEAR(A401) -> 2022 | F401: =MONTH(A401) -> 2 | G401: 24.9 | H401: 51.5 | I401: 92 | J401: 3.9 | K401: 3.2 | L401: วันทำงานปกติ
A402: 44597 | B402: 14 | C402: =IF(NOT(ISNUMBER(B402)),"",ROUND((INDEX(BP!$D$5:$D$9,MATCH(B402,BP!$A$5:$A$9,1))-INDEX(BP!$C$5:$C$9,MATCH(B402,BP!$A$5:$A$9,1)))/(INDEX(BP!$B$5:$B$9,MATCH(B402,BP!$A$5:$A$9,1))-INDEX(BP!$A$5:$A$9,MATCH(B402,BP!$A$5:$A$9,1)))*(B402-INDEX(BP!$A$5:$A$9,MATCH(B402,BP!$A$5:$A$9,1)))+INDEX(BP!$C$5:$C$9,MATCH(B402,BP!$A$5:$A$9,1)),0)) -> 23 | D402: =IF(NOT(ISNUMBER(C402)),"",INDEX(BP!$F$5:$F$9,MATCH(C402,BP!$E$5:$E$9,1))) -> ดีมาก | E402: =YEAR(A402) -> 2022 | F402: =MONTH(A402) -> 2 | G402: 26.4 | H402: 54.7 | I402: 96 | J402: 1.3 | K402: 0.2 | L402: วันหยุดสุดสัปดาห์
A403: 44598 | B403: 15 | C403: =IF(NOT(ISNUMBER(B403)),"",ROUND((INDEX(BP!$D$5:$D$9,MATCH(B403,BP!$A$5:$A$9,1))-INDEX(BP!$C$5:$C$9,MATCH(B403,BP!$A$5:$A$9,1)))/(INDEX(BP!$B$5:$B$9,MATCH(B403,BP!$A$5:$A$9,1))-INDEX(BP!$A$5:$A$9,MATCH(B403,BP!$A$5:$A$9,1)))*(B403-INDEX(BP!$A$5:$A$9,MATCH(B403,BP!$A$5:$A$9,1)))+INDEX(BP!$C$5:$C$9,MATCH(B403,BP!$A$5:$A$9,1)),0)) -> 25 | D403: =IF(NOT(ISNUMBER(C403)),"",INDEX(BP!$F$5:$F$9,MATCH(C403,BP!$E$5:$E$9,1))) -> ดีมาก | E403: =YEAR(A403) -> 2022 | F403: =MONTH(A403) -> 2 | G403: 24.1 | H403: 50 | I403: 95 | J403: 0.6 | K403: 0 | L403: วันหยุดสุดสัปดาห์
A404: 44599 | B404: 14 | C404: =IF(NOT(ISNUMBER(B404)),"",ROUND((INDEX(BP!$D$5:$D$9,MATCH(B404,BP!$A$5:$A$9,1))-INDEX(BP!$C$5:$C$9,MATCH(B404,BP!$A$5:$A$9,1)))/(INDEX(BP!$B$5:$B$9,MATCH(B404,BP!$A$5:$A$9,1))-INDEX(BP!$A$5:$A$9,MATCH(B404,BP!$A$5:$A$9,1)))*(B404-INDEX(BP!$A$5:$A$9,MATCH(B404,BP!$A$5:$A$9,1)))+INDEX(BP!$C$5:$C$9,MATCH(B404,BP!$A$5:$A$9,1)),0)) -> 23 | D404: =IF(NOT(ISNUMBER(C404)),"",INDEX(BP!$F$5:$F$9,MATCH(C404,BP!$E$5:$E$9,1))) -> ดีมาก | E404: =YEAR(A404) -> 2022 | F404: =MONTH(A404) -> 2 | G404: 18.9 | H404: 42.5 | I404: 84 | J404: 2.1 | K404: 0.6 | L404: วันทำงานปกติ
A405: 44600 | B405: 15 | C405: =IF(NOT(ISNUMBER(B405)),"",ROUND((INDEX(BP!$D$5:$D$9,MATCH(B405,BP!$A$5:$A$9,1))-INDEX(BP!$C$5:$C$9,MATCH(B405,BP!$A$5:$A$9,1)))/(INDEX(BP!$B$5:$B$9,MATCH(B405,BP!$A$5:$A$9,1))-INDEX(BP!$A$5:$A$9,MATCH(B405,BP!$A$5:$A$9,1)))*(B405-INDEX(BP!$A$5:$A$9,MATCH(B405,BP!$A$5:$A$9,1)))+INDEX(BP!$C$5:$C$9,MATCH(B405,BP!$A$5:$A$9,1)),0)) -> 25 | D405: =IF(NOT(ISNUMBER(C405)),"",INDEX(BP!$F$5:$F$9,MATCH(C405,BP!$E$5:$E$9,1))) -> ดีมาก | E405: =YEAR(A405) -> 2022 | F405: =MONTH(A405) -> 2 | G405: 20 | H405: 43.9 | I405: 76 | J405: 2.4 | K405: 1.8 | L405: วันทำงานปกติ
A406: 44601 | B406: 15 | C406: =IF(NOT(ISNUMBER(B406)),"",ROUND((INDEX(BP!$D$5:$D$9,MATCH(B406,BP!$A$5:$A$9,1))-INDEX(BP!$C$5:$C$9,MATCH(B406,BP!$A$5:$A$9,1)))/(INDEX(BP!$B$5:$B$9,MATCH(B406,BP!$A$5:$A$9,1))-INDEX(BP!$A$5:$A$9,MATCH(B406,BP!$A$5:$A$9,1)))*(B406-INDEX(BP!$A$5:$A$9,MATCH(B406,BP!$A$5:$A$9,1)))+INDEX(BP!$C$5:$C$9,MATCH(B406,BP!$A$5:$A$9,1)),0)) -> 25 | D406: =IF(NOT(ISNUMBER(C406)),"",INDEX(BP!$F$5:$F$9,MATCH(C406,BP!$E$5:$E$9,1))) -> ดีมาก | E406: =YEAR(A406) -> 2022 | F406: =MONTH(A406) -> 2 | G406: 18.3 | H406: 39.2 | I406: 94 | J406: 1 | K406: 0 | L406: วันทำงานปกติ
A407: 44602 | B407: 18 | C407: =IF(NOT(ISNUMBER(B407)),"",ROUND((INDEX(BP!$D$5:$D$9,MATCH(B407,BP!$A$5:$A$9,1))-INDEX(BP!$C$5:$C$9,MATCH(B407,BP!$A$5:$A$9,1)))/(INDEX(BP!$B$5:$B$9,MATCH(B407,BP!$A$5:$A$9,1))-INDEX(BP!$A$5:$A$9,MATCH(B407,BP!$A$5:$A$9,1)))*(B407-INDEX(BP!$A$5:$A$9,MATCH(B407,BP!$A$5:$A$9,1)))+INDEX(BP!$C$5:$C$9,MATCH(B407,BP!$A$5:$A$9,1)),0)) -> 33 | D407: =IF(NOT(ISNUMBER(C407)),"",INDEX(BP!$F$5:$F$9,MATCH(C407,BP!$E$5:$E$9,1))) -> ดี | E407: =YEAR(A407) -> 2022 | F407: =MONTH(A407) -> 2 | G407: 15.4 | H407: 34.6 | I407: 96 | J407: 0.2 | K407: 0 | L407: วันทำงานปกติ
A408: 44603 | B408: 19 | C408: =IF(NOT(ISNUMBER(B408)),"",ROUND((INDEX(BP!$D$5:$D$9,MATCH(B408,BP!$A$5:$A$9,1))-INDEX(BP!$C$5:$C$9,MATCH(B408,BP!$A$5:$A$9,1)))/(INDEX(BP!$B$5:$B$9,MATCH(B408,BP!$A$5:$A$9,1))-INDEX(BP!$A$5:$A$9,MATCH(B408,BP!$A$5:$A$9,1)))*(B408-INDEX(BP!$A$5:$A$9,MATCH(B408,BP!$A$5:$A$9,1)))+INDEX(BP!$C$5:$C$9,MATCH(B408,BP!$A$5:$A$9,1)),0)) -> 35 | D408: =IF(NOT(ISNUMBER(C408)),"",INDEX(BP!$F$5:$F$9,MATCH(C408,BP!$E$5:$E$9,1))) -> ดี | E408: =YEAR(A408) -> 2022 | F408: =MONTH(A408) -> 2 | G408: 20.3 | H408: 43.2 | I408: 96 | J408: 0.4 | K408: 0 | L408: วันทำงานปกติ
A409: 44604 | B409: 20 | C409: =IF(NOT(ISNUMBER(B409)),"",ROUND((INDEX(BP!$D$5:$D$9,MATCH(B409,BP!$A$5:$A$9,1))-INDEX(BP!$C$5:$C$9,MATCH(B409,BP!$A$5:$A$9,1)))/(INDEX(BP!$B$5:$B$9,MATCH(B409,BP!$A$5:$A$9,1))-INDEX(BP!$A$5:$A$9,MATCH(B409,BP!$A$5:$A$9,1)))*(B409-INDEX(BP!$A$5:$A$9,MATCH(B409,BP!$A$5:$A$9,1)))+INDEX(BP!$C$5:$C$9,MATCH(B409,BP!$A$5:$A$9,1)),0)) -> 38 | D409: =IF(NOT(ISNUMBER(C409)),"",INDEX(BP!$F$5:$F$9,MATCH(C409,BP!$E$5:$E$9,1))) -> ดี | E409: =YEAR(A409) -> 2022 | F409: =MONTH(A409) -> 2 | G409: 20.5 | H409: 42.8 | I409: 71 | J409: 1 | K409: 0.4 | L409: วันหยุดสุดสัปดาห์
A410: 44605 | B410: 15 | C410: =IF(NOT(ISNUMBER(B410)),"",ROUND((INDEX(BP!$D$5:$D$9,MATCH(B410,BP!$A$5:$A$9,1))-INDEX(BP!$C$5:$C$9,MATCH(B410,BP!$A$5:$A$9,1)))/(INDEX(BP!$B$5:$B$9,MATCH(B410,BP!$A$5:$A$9,1))-INDEX(BP!$A$5:$A$9,MATCH(B410,BP!$A$5:$A$9,1)))*(B410-INDEX(BP!$A$5:$A$9,MATCH(B410,BP!$A$5:$A$9,1)))+INDEX(BP!$C$5:$C$9,MATCH(B410,BP!$A$5:$A$9,1)),0)) -> 25 | D410: =IF(NOT(ISNUMBER(C410)),"",INDEX(BP!$F$5:$F$9,MATCH(C410,BP!$E$5:$E$9,1))) -> ดีมาก | E410: =YEAR(A410) -> 2022 | F410: =MONTH(A410) -> 2 | G410: 21.7 | H410: 46.1 | I410: 82 | J410: 1.3 | K410: 0 | L410: วันหยุดสุดสัปดาห์
A411: 44606 | B411: 8 | C411: =IF(NOT(ISNUMBER(B411)),"",ROUND((INDEX(BP!$D$5:$D$9,MATCH(B411,BP!$A$5:$A$9,1))-INDEX(BP!$C$5:$C$9,MATCH(B411,BP!$A$5:$A$9,1)))/(INDEX(BP!$B$5:$B$9,MATCH(B411,BP!$A$5:$A$9,1))-INDEX(BP!$A$5:$A$9,MATCH(B411,BP!$A$5:$A$9,1)))*(B411-INDEX(BP!$A$5:$A$9,MATCH(B411,BP!$A$5:$A$9,1)))+INDEX(BP!$C$5:$C$9,MATCH(B411,BP!$A$5:$A$9,1)),0)) -> 13 | D411: =IF(NOT(ISNUMBER(C411)),"",INDEX(BP!$F$5:$F$9,MATCH(C411,BP!$E$5:$E$9,1))) -> ดีมาก | E411: =YEAR(A411) -> 2022 | F411: =MONTH(A411) -> 2 | G411: 22 | H411: 45.7 | I411: 101 | J411: 4.6 | K411: 3.4 | L411: วันทำงานปกติ
A412: 44607 | B412: 10 | C412: =IF(NOT(ISNUMBER(B412)),"",ROUND((INDEX(BP!$D$5:$D$9,MATCH(B412,BP!$A$5:$A$9,1))-INDEX(BP!$C$5:$C$9,MATCH(B412,BP!$A$5:$A$9,1)))/(INDEX(BP!$B$5:$B$9,MATCH(B412,BP!$A$5:$A$9,1))-INDEX(BP!$A$5:$A$9,MATCH(B412,BP!$A$5:$A$9,1)))*(B412-INDEX(BP!$A$5:$A$9,MATCH(B412,BP!$A$5:$A$9,1)))+INDEX(BP!$C$5:$C$9,MATCH(B412,BP!$A$5:$A$9,1)),0)) -> 17 | D412: =IF(NOT(ISNUMBER(C412)),"",INDEX(BP!$F$5:$F$9,MATCH(C412,BP!$E$5:$E$9,1))) -> ดีมาก | E412: =YEAR(A412) -> 2022 | F412: =MONTH(A412) -> 2 | G412: 20.9 | H412: 42.1 | I412: 106 | J412: 23 | K412: 0.4 | L412: วันทำงานปกติ
... A439: 44634 | B439: 13 | C439: =IF(NOT(ISNUMBER(B439)),"",ROUND((INDEX(BP!$D$5:$D$9,MATCH(B439,BP!$A$5:$A$9,1))-INDEX(BP!$C$5:$C$9,MATCH(B439,BP!$A$5:$A$9,1)))/(INDEX(BP!$B$5:$B$9,MATCH(B439,BP!$A$5:$A$9,1))-INDEX(BP!$A$5:$A$9,MATCH(B439,BP!$A$5:$A$9,1)))*(B439-INDEX(BP!$A$5:$A$9,MATCH(B439,BP!$A$5:$A$9,1)))+INDEX(BP!$C$5:$C$9,MATCH(B439,BP!$A$5:$A$9,1)),0)) -> 22 | D439: =IF(NOT(ISNUMBER(C439)),"",INDEX(BP!$F$5:$F$9,MATCH(C439,BP!$E$5:$E$9,1))) -> ดีมาก | E439: =YEAR(A439) -> 2022 | F439: =MONTH(A439) -> 3 | G439: 21.1 | H439: 44.3 | I439: 91 | J439: 24.5 | K439: 21.6 | L439: วันทำงานปกติ
A440: 44635 | C440: =IF(NOT(ISNUMBER(B440)),"",ROUND((INDEX(BP!$D$5:$D$9,MATCH(B440,BP!$A$5:$A$9,1))-INDEX(BP!$C$5:$C$9,MATCH(B440,BP!$A$5:$A$9,1)))/(INDEX(BP!$B$5:$B$9,MATCH(B440,BP!$A$5:$A$9,1))-INDEX(BP!$A$5:$A$9,MATCH(B440,BP!$A$5:$A$9,1)))*(B440-INDEX(BP!$A$5:$A$9,MATCH(B440,BP!$A$5:$A$9,1)))+INDEX(BP!$C$5:$C$9,MATCH(B440,BP!$A$5:$A$9,1)),0)) | D440: =IF(NOT(ISNUMBER(C440)),"",INDEX(BP!$F$5:$F$9,MATCH(C440,BP!$E$5:$E$9,1))) | E440: =YEAR(A440) -> 2022 | F440: =MONTH(A440) -> 3 | G440: 15.8 | H440: 34.6 | I440: 90 | J440: 0.3 | K440: 0 | L440: วันทำงานปกติ
A441: 44636 | B441: 14 | C441: =IF(NOT(ISNUMBER(B441)),"",ROUND((INDEX(BP!$D$5:$D$9,MATCH(B441,BP!$A$5:$A$9,1))-INDEX(BP!$C$5:$C$9,MATCH(B441,BP!$A$5:$A$9,1)))/(INDEX(BP!$B$5:$B$9,MATCH(B441,BP!$A$5:$A$9,1))-INDEX(BP!$A$5:$A$9,MATCH(B441,BP!$A$5:$A$9,1)))*(B441-INDEX(BP!$A$5:$A$9,MATCH(B441,BP!$A$5:$A$9,1)))+INDEX(BP!$C$5:$C$9,MATCH(B441,BP!$A$5:$A$9,1)),0)) -> 23 | D441: =IF(NOT(ISNUMBER(C441)),"",INDEX(BP!$F$5:$F$9,MATCH(C441,BP!$E$5:$E$9,1))) -> ดีมาก | E441: =YEAR(A441) -> 2022 | F441: =MONTH(A441) -> 3 | G441: 12.7 | H441: 29.9 | I441: 90 | J441: 0.2 | K441: 0 | L441: วันทำงานปกติ
A442: 44637 | B442: 12 | C442: =IF(NOT(ISNUMBER(B442)),"",ROUND((INDEX(BP!$D$5:$D$9,MATCH(B442,BP!$A$5:$A$9,1))-INDEX(BP!$C$5:$C$9,MATCH(B442,BP!$A$5:$A$9,1)))/(INDEX(BP!$B$5:$B$9,MATCH(B442,BP!$A$5:$A$9,1))-INDEX(BP!$A$5:$A$9,MATCH(B442,BP!$A$5:$A$9,1)))*(B442-INDEX(BP!$A$5:$A$9,MATCH(B442,BP!$A$5:$A$9,1)))+INDEX(BP!$C$5:$C$9,MATCH(B442,BP!$A$5:$A$9,1)),0)) -> 20 | D442: =IF(NOT(ISNUMBER(C442)),"",INDEX(BP!$F$5:$F$9,MATCH(C442,BP!$E$5:$E$9,1))) -> ดีมาก | E442: =YEAR(A442) -> 2022 | F442: =MONTH(A442) -> 3 | G442: 15.9 | H442: 34.6 | I442: 100 | J442: 2.2 | K442: 2.4 | L442: วันทำงานปกติ
A443: 44638 | B443: 14 | C443: =IF(NOT(ISNUMBER(B443)),"",ROUND((INDEX(BP!$D$5:$D$9,MATCH(B443,BP!$A$5:$A$9,1))-INDEX(BP!$C$5:$C$9,MATCH(B443,BP!$A$5:$A$9,1)))/(INDEX(BP!$B$5:$B$9,MATCH(B443,BP!$A$5:$A$9,1))-INDEX(BP!$A$5:$A$9,MATCH(B443,BP!$A$5:$A$9,1)))*(B443-INDEX(BP!$A$5:$A$9,MATCH(B443,BP!$A$5:$A$9,1)))+INDEX(BP!$C$5:$C$9,MATCH(B443,BP!$A$5:$A$9,1)),0)) -> 23 | D443: =IF(NOT(ISNUMBER(C443)),"",INDEX(BP!$F$5:$F$9,MATCH(C443,BP!$E$5:$E$9,1))) -> ดีมาก | E443: =YEAR(A443) -> 2022 | F443: =MONTH(A443) -> 3 | G443: 11.6 | H443: 28.8 | I443: 109 | J443: 0.8 | K443: 2.2 | L443: วันทำงานปกติ
A444: 44639 | B444: 14 | C444: =IF(NOT(ISNUMBER(B444)),"",ROUND((INDEX(BP!$D$5:$D$9,MATCH(B444,BP!$A$5:$A$9,1))-INDEX(BP!$C$5:$C$9,MATCH(B444,BP!$A$5:$A$9,1)))/(INDEX(BP!$B$5:$B$9,MATCH(B444,BP!$A$5:$A$9,1))-INDEX(BP!$A$5:$A$9,MATCH(B444,BP!$A$5:$A$9,1)))*(B444-INDEX(BP!$A$5:$A$9,MATCH(B444,BP!$A$5:$A$9,1)))+INDEX(BP!$C$5:$C$9,MATCH(B444,BP!$A$5:$A$9,1)),0)) -> 23 | D444: =IF(NOT(ISNUMBER(C444)),"",INDEX(BP!$F$5:$F$9,MATCH(C444,BP!$E$5:$E$9,1))) -> ดีมาก | E444: =YEAR(A444) -> 2022 | F444: =MONTH(A444) -> 3 | G444: 13.2 | H444: 30.2 | I444: 115 | J444: 22.2 | K444: 0.2 | L444: วันหยุดสุดสัปดาห์
A445: 44640 | B445: 13 | C445: =IF(NOT(ISNUMBER(B445)),"",ROUND((INDEX(BP!$D$5:$D$9,MATCH(B445,BP!$A$5:$A$9,1))-INDEX(BP!$C$5:$C$9,MATCH(B445,BP!$A$5:$A$9,1)))/(INDEX(BP!$B$5:$B$9,MATCH(B445,BP!$A$5:$A$9,1))-INDEX(BP!$A$5:$A$9,MATCH(B445,BP!$A$5:$A$9,1)))*(B445-INDEX(BP!$A$5:$A$9,MATCH(B445,BP!$A$5:$A$9,1)))+INDEX(BP!$C$5:$C$9,MATCH(B445,BP!$A$5:$A$9,1)),0)) -> 22 | D445: =IF(NOT(ISNUMBER(C445)),"",INDEX(BP!$F$5:$F$9,MATCH(C445,BP!$E$5:$E$9,1))) -> ดีมาก | E445: =YEAR(A445) -> 2022 | F445: =MONTH(A445) -> 3 | G445: 10.7 | H445: 29.5 | I445: 118 | J445: 19.2 | K445: 8.4 | L445: วันหยุดสุดสัปดาห์
A446: 44641 | B446: 14 | C446: =IF(NOT(ISNUMBER(B446)),"",ROUND((INDEX(BP!$D$5:$D$9,MATCH(B446,BP!$A$5:$A$9,1))-INDEX(BP!$C$5:$C$9,MATCH(B446,BP!$A$5:$A$9,1)))/(INDEX(BP!$B$5:$B$9,MATCH(B446,BP!$A$5:$A$9,1))-INDEX(BP!$A$5:$A$9,MATCH(B446,BP!$A$5:$A$9,1)))*(B446-INDEX(BP!$A$5:$A$9,MATCH(B446,BP!$A$5:$A$9,1)))+INDEX(BP!$C$5:$C$9,MATCH(B446,BP!$A$5:$A$9,1)),0)) -> 23 | D446: =IF(NOT(ISNUMBER(C446)),"",INDEX(BP!$F$5:$F$9,MATCH(C446,BP!$E$5:$E$9,1))) -> ดีมาก | E446: =YEAR(A446) -> 2022 | F446: =MONTH(A446) -> 3 | G446: 8.9 | H446: 24.1 | I446: 164 | J446: 14.7 | K446: 0 | L446: วันทำงานปกติ
A447: 44642 | B447: 12 | C447: =IF(NOT(ISNUMBER(B447)),"",ROUND((INDEX(BP!$D$5:$D$9,MATCH(B447,BP!$A$5:$A$9,1))-INDEX(BP!$C$5:$C$9,MATCH(B447,BP!$A$5:$A$9,1)))/(INDEX(BP!$B$5:$B$9,MATCH(B447,BP!$A$5:$A$9,1))-INDEX(BP!$A$5:$A$9,MATCH(B447,BP!$A$5:$A$9,1)))*(B447-INDEX(BP!$A$5:$A$9,MATCH(B447,BP!$A$5:$A$9,1)))+INDEX(BP!$C$5:$C$9,MATCH(B447,BP!$A$5:$A$9,1)),0)) -> 20 | D447: =IF(NOT(ISNUMBER(C447)),"",INDEX(BP!$F$5:$F$9,MATCH(C447,BP!$E$5:$E$9,1))) -> ดีมาก | E447: =YEAR(A447) -> 2022 | F447: =MONTH(A447) -> 3 | G447: 11.2 | H447: 25.9 | I447: 105 | J447: 4.9 | K447: 11.2 | L447: วันทำงานปกติ
A448: 44643 | B448: 14 | C448: =IF(NOT(ISNUMBER(B448)),"",ROUND((INDEX(BP!$D$5:$D$9,MATCH(B448,BP!$A$5:$A$9,1))-INDEX(BP!$C$5:$C$9,MATCH(B448,BP!$A$5:$A$9,1)))/(INDEX(BP!$B$5:$B$9,MATCH(B448,BP!$A$5:$A$9,1))-INDEX(BP!$A$5:$A$9,MATCH(B448,BP!$A$5:$A$9,1)))*(B448-INDEX(BP!$A$5:$A$9,MATCH(B448,BP!$A$5:$A$9,1)))+INDEX(BP!$C$5:$C$9,MATCH(B448,BP!$A$5:$A$9,1)),0)) -> 23 | D448: =IF(NOT(ISNUMBER(C448)),"",INDEX(BP!$F$5:$F$9,MATCH(C448,BP!$E$5:$E$9,1))) -> ดีมาก | E448: =YEAR(A448) -> 2022 | F448: =MONTH(A448) -> 3 | G448: 10.7 | H448: 23 | I448: 102 | J448: 4.3 | K448: 0 | L448: วันทำงานปกติ
A449: 44644 | B449: 15 | C449: =IF(NOT(ISNUMBER(B449)),"",ROUND((INDEX(BP!$D$5:$D$9,MATCH(B449,BP!$A$5:$A$9,1))-INDEX(BP!$C$5:$C$9,MATCH(B449,BP!$A$5:$A$9,1)))/(INDEX(BP!$B$5:$B$9,MATCH(B449,BP!$A$5:$A$9,1))-INDEX(BP!$A$5:$A$9,MATCH(B449,BP!$A$5:$A$9,1)))*(B449-INDEX(BP!$A$5:$A$9,MATCH(B449,BP!$A$5:$A$9,1)))+INDEX(BP!$C$5:$C$9,MATCH(B449,BP!$A$5:$A$9,1)),0)) -> 25 | D449: =IF(NOT(ISNUMBER(C449)),"",INDEX(BP!$F$5:$F$9,MATCH(C449,BP!$E$5:$E$9,1))) -> ดีมาก | E449: =YEAR(A449) -> 2022 | F449: =MONTH(A449) -> 3 | G449: 12.5 | H449: 29.9 | I449: 81 | J449: 0.5 | K449: 0 | L449: วันทำงานปกติ
A450: 44645 | B450: 15 | C450: =IF(NOT(ISNUMBER(B450)),"",ROUND((INDEX(BP!$D$5:$D$9,MATCH(B450,BP!$A$5:$A$9,1))-INDEX(BP!$C$5:$C$9,MATCH(B450,BP!$A$5:$A$9,1)))/(INDEX(BP!$B$5:$B$9,MATCH(B450,BP!$A$5:$A$9,1))-INDEX(BP!$A$5:$A$9,MATCH(B450,BP!$A$5:$A$9,1)))*(B450-INDEX(BP!$A$5:$A$9,MATCH(B450,BP!$A$5:$A$9,1)))+INDEX(BP!$C$5:$C$9,MATCH(B450,BP!$A$5:$A$9,1)),0)) -> 25 | D450: =IF(NOT(ISNUMBER(C450)),"",INDEX(BP!$F$5:$F$9,MATCH(C450,BP!$E$5:$E$9,1))) -> ดีมาก | E450: =YEAR(A450) -> 2022 | F450: =MONTH(A450) -> 3 | G450: 10.2 | H450: 27.4 | I450: 93 | J450: 3.7 | K450: 0 | L450: วันทำงานปกติ
A451: 44646 | B451: 17 | C451: =IF(NOT(ISNUMBER(B451)),"",ROUND((INDEX(BP!$D$5:$D$9,MATCH(B451,BP!$A$5:$A$9,1))-INDEX(BP!$C$5:$C$9,MATCH(B451,BP!$A$5:$A$9,1)))/(INDEX(BP!$B$5:$B$9,MATCH(B451,BP!$A$5:$A$9,1))-INDEX(BP!$A$5:$A$9,MATCH(B451,BP!$A$5:$A$9,1)))*(B451-INDEX(BP!$A$5:$A$9,MATCH(B451,BP!$A$5:$A$9,1)))+INDEX(BP!$C$5:$C$9,MATCH(B451,BP!$A$5:$A$9,1)),0)) -> 31 | D451: =IF(NOT(ISNUMBER(C451)),"",INDEX(BP!$F$5:$F$9,MATCH(C451,BP!$E$5:$E$9,1))) -> ดี | E451: =YEAR(A451) -> 2022 | F451: =MONTH(A451) -> 3 | G451: 11.5 | H451: 28.4 | I451: 75 | J451: 1 | K451: 0 | L451: วันหยุดสุดสัปดาห์
...

Sheet Summary
A1: สรุปผลการวิเคราะห์ AQI จาก PM2.5 สถานี 44T หาดใหญ่ (2021–2025)
A3: 1) ภาพรวมทั้งชุดข้อมูล | D3: 2) จำนวนวันแยกตามระดับคุณภาพอากาศ
A4: จำนวนวันที่มีค่าตรวจวัด | B4: =COUNT(Data!$C$2:$C$1827) -> 1804 | D4: ระดับ | E4: ช่วง AQI | F4: จำนวนวัน | G4: สัดส่วน
A5: PM2.5 เฉลี่ย (มคก./ลบ.ม.) | B5: =ROUND(AVERAGE(Data!$B$2:$B$1827),2) -> 14.93 | D5: ดีมาก | E5: 0–25 | F5: =COUNTIFS(Data!$C$2:$C$1827,">=0",Data!$C$2:$C$1827,"<=25") -> 1031 | G5: =IFERROR(F5/SUM($F$5:$F$9),0) -> 0.57150776
A6: AQI เฉลี่ย | B6: =ROUND(AVERAGE(Data!$C$2:$C$1827),2) -> 27 | D6: ดี | E6: 26–50 | F6: =COUNTIFS(Data!$C$2:$C$1827,">=26",Data!$C$2:$C$1827,"<=50") -> 717 | G6: =IFERROR(F6/SUM($F$5:$F$9),0) -> 0.39745011
A7: AQI ต่ำสุด | B7: =MIN(Data!$C$2:$C$1827) -> 9 | D7: ปานกลาง | E7: 51–100 | F7: =COUNTIFS(Data!$C$2:$C$1827,">=51",Data!$C$2:$C$1827,"<=100") -> 49 | G7: =IFERROR(F7/SUM($F$5:$F$9),0) -> 0.027161863
A8: AQI สูงสุด | B8: =MAX(Data!$C$2:$C$1827) -> 119 | D8: เริ่มมีผลกระทบต่อสุขภาพ | E8: 101–200 | F8: =COUNTIFS(Data!$C$2:$C$1827,">=101",Data!$C$2:$C$1827,"<=200") -> 7 | G8: =IFERROR(F8/SUM($F$5:$F$9),0) -> 0.0038802661
A9: มัธยฐาน AQI | B9: =MEDIAN(Data!$C$2:$C$1827) -> 24 | D9: มีผลกระทบต่อสุขภาพ | E9: 201+ | F9: =COUNTIFS(Data!$C$2:$C$1827,">=201",Data!$C$2:$C$1827,"<=100000") -> 0 | G9: =IFERROR(F9/SUM($F$5:$F$9),0) -> 0
A10: ส่วนเบี่ยงเบนมาตรฐาน | B10: =ROUND(STDEV(Data!$C$2:$C$1827),2) -> 12.58 | D10: รวม | F10: =SUM(F5:F9) -> 1804
A11: วันที่ AQI > 100 (ส้ม/แดง) | B11: =COUNTIF(Data!$C$2:$C$1827,">100") -> 7
A12: วันที่ PM2.5 เกินมาตรฐาน 37.5 | B12: =COUNTIF(Data!$B$2:$B$1827,">37.5") -> 7
A15: 3) สรุปรายปี | I15: 5) AQI เฉลี่ยตามประเภทวัน
A16: ปี | B16: PM2.5 เฉลี่ย | C16: AQI เฉลี่ย | D16: AQI สูงสุด | E16: วัน AQI>50 | F16: วัน AQI>100 | G16: จำนวนวัน | I16: ประเภทวัน | J16: AQI เฉลี่ย | K16: จำนวนวัน
A17: 2021 | B17: =ROUND(AVERAGEIFS(Data!$B$2:$B$1827,Data!$E$2:$E$1827,$A17),2) -> 16.68 | C17: =ROUND(AVERAGEIFS(Data!$C$2:$C$1827,Data!$E$2:$E$1827,$A17),2) -> 30.51 | D17: =_xlfn.MAXIFS(Data!$C$2:$C$1827,Data!$E$2:$E$1827,$A17) -> 102 | E17: =COUNTIFS(Data!$E$2:$E$1827,$A17,Data!$C$2:$C$1827,">50") -> 16 | F17: =COUNTIFS(Data!$E$2:$E$1827,$A17,Data!$C$2:$C$1827,">100") -> 1 | G17: =COUNTIFS(Data!$E$2:$E$1827,$A17,Data!$C$2:$C$1827,">=0") -> 365 | I17: วันทำงานปกติ | J17: =ROUND(AVERAGEIFS(Data!$C$2:$C$1827,Data!$L$2:$L$1827,$I17),2) -> 26.71 | K17: =COUNTIFS(Data!$L$2:$L$1827,$I17,Data!$C$2:$C$1827,">=0") -> 1179
A18: 2022 | B18: =ROUND(AVERAGEIFS(Data!$B$2:$B$1827,Data!$E$2:$E$1827,$A18),2) -> 15.92 | C18: =ROUND(AVERAGEIFS(Data!$C$2:$C$1827,Data!$E$2:$E$1827,$A18),2) -> 28.52 | D18: =_xlfn.MAXIFS(Data!$C$2:$C$1827,Data!$E$2:$E$1827,$A18) -> 78 | E18: =COUNTIFS(Data!$E$2:$E$1827,$A18,Data!$C$2:$C$1827,">50") -> 9 | F18: =COUNTIFS(Data!$E$2:$E$1827,$A18,Data!$C$2:$C$1827,">100") -> 0 | G18: =COUNTIFS(Data!$E$2:$E$1827,$A18,Data!$C$2:$C$1827,">=0") -> 362 | I18: วันหยุดสุดสัปดาห์ | J18: =ROUND(AVERAGEIFS(Data!$C$2:$C$1827,Data!$L$2:$L$1827,$I18),2) -> 26.91 | K18: =COUNTIFS(Data!$L$2:$L$1827,$I18,Data!$C$2:$C$1827,">=0") -> 490
A19: 2023 | B19: =ROUND(AVERAGEIFS(Data!$B$2:$B$1827,Data!$E$2:$E$1827,$A19),2) -> 16.61 | C19: =ROUND(AVERAGEIFS(Data!$C$2:$C$1827,Data!$E$2:$E$1827,$A19),2) -> 31.02 | D19: =_xlfn.MAXIFS(Data!$C$2:$C$1827,Data!$E$2:$E$1827,$A19) -> 119 | E19: =COUNTIFS(Data!$E$2:$E$1827,$A19,Data!$C$2:$C$1827,">50") -> 24 | F19: =COUNTIFS(Data!$E$2:$E$1827,$A19,Data!$C$2:$C$1827,">100") -> 6 | G19: =COUNTIFS(Data!$E$2:$E$1827,$A19,Data!$C$2:$C$1827,">=0") -> 363 | I19: วันหยุดราชการ/นักขัตฤกษ์ | J19: =ROUND(AVERAGEIFS(Data!$C$2:$C$1827,Data!$L$2:$L$1827,$I19),2) -> 29.8 | K19: =COUNTIFS(Data!$L$2:$L$1827,$I19,Data!$C$2:$C$1827,">=0") -> 135
A20: 2024 | B20: =ROUND(AVERAGEIFS(Data!$B$2:$B$1827,Data!$E$2:$E$1827,$A20),2) -> 14.3 | C20: =ROUND(AVERAGEIFS(Data!$C$2:$C$1827,Data!$E$2:$E$1827,$A20),2) -> 25.48 | D20: =_xlfn.MAXIFS(Data!$C$2:$C$1827,Data!$E$2:$E$1827,$A20) -> 56 | E20: =COUNTIFS(Data!$E$2:$E$1827,$A20,Data!$C$2:$C$1827,">50") -> 6 | F20: =COUNTIFS(Data!$E$2:$E$1827,$A20,Data!$C$2:$C$1827,">100") -> 0 | G20: =COUNTIFS(Data!$E$2:$E$1827,$A20,Data!$C$2:$C$1827,">=0") -> 365
A21: 2025 | B21: =ROUND(AVERAGEIFS(Data!$B$2:$B$1827,Data!$E$2:$E$1827,$A21),2) -> 10.99 | C21: =ROUND(AVERAGEIFS(Data!$C$2:$C$1827,Data!$E$2:$E$1827,$A21),2) -> 19.13 | D21: =_xlfn.MAXIFS(Data!$C$2:$C$1827,Data!$E$2:$E$1827,$A21) -> 53 | E21: =COUNTIFS(Data!$E$2:$E$1827,$A21,Data!$C$2:$C$1827,">50") -> 1 | F21: =COUNTIFS(Data!$E$2:$E$1827,$A21,Data!$C$2:$C$1827,">100") -> 0 | G21: =COUNTIFS(Data!$E$2:$E$1827,$A21,Data!$C$2:$C$1827,">=0") -> 349
A24: 4) สรุปรายเดือน (เฉลี่ยรวมทุกปี) | I24: 6) ความสัมพันธ์กับสภาพอากาศ (สัมประสิทธิ์สหสัมพันธ์กับ AQI)
A25: เดือน | B25: PM2.5 เฉลี่ย | C25: AQI เฉลี่ย | D25: AQI สูงสุด | I25: ความเร็วลมสูงสุด | J25: =ROUND(CORREL(Data!$G$2:$G$1827,Data!$C$2:$C$1827),3) -> -0.104
A26: ม.ค. | B26: =ROUND(AVERAGEIFS(Data!$B$2:$B$1827,Data!$F$2:$F$1827,1),2) -> 17.35 | C26: =ROUND(AVERAGEIFS(Data!$C$2:$C$1827,Data!$F$2:$F$1827,1),2) -> 31.82 | D26: =_xlfn.MAXIFS(Data!$C$2:$C$1827,Data!$F$2:$F$1827,1) -> 86 | I26: ลมกระโชกสูงสุด | J26: =ROUND(CORREL(Data!$H$2:$H$1827,Data!$C$2:$C$1827),3) -> -0.083
A27: ก.พ. | B27: =ROUND(AVERAGEIFS(Data!$B$2:$B$1827,Data!$F$2:$F$1827,2),2) -> 16.88 | C27: =ROUND(AVERAGEIFS(Data!$C$2:$C$1827,Data!$F$2:$F$1827,2),2) -> 31.45 | D27: =_xlfn.MAXIFS(Data!$C$2:$C$1827,Data!$F$2:$F$1827,2) -> 102 | I27: ทิศลมหลัก | J27: =ROUND(CORREL(Data!$I$2:$I$1827,Data!$C$2:$C$1827),3) -> -0.113
A28: มี.ค. | B28: =ROUND(AVERAGEIFS(Data!$B$2:$B$1827,Data!$F$2:$F$1827,3),2) -> 17.12 | C28: =ROUND(AVERAGEIFS(Data!$C$2:$C$1827,Data!$F$2:$F$1827,3),2) -> 31.42 | D28: =_xlfn.MAXIFS(Data!$C$2:$C$1827,Data!$F$2:$F$1827,3) -> 78 | I28: ฝน (model) | J28: =ROUND(CORREL(Data!$J$2:$J$1827,Data!$C$2:$C$1827),3) -> -0.234
A29: เม.ย. | B29: =ROUND(AVERAGEIFS(Data!$B$2:$B$1827,Data!$F$2:$F$1827,4),2) -> 17.94 | C29: =ROUND(AVERAGEIFS(Data!$C$2:$C$1827,Data!$F$2:$F$1827,4),2) -> 35.19 | D29: =_xlfn.MAXIFS(Data!$C$2:$C$1827,Data!$F$2:$F$1827,4) -> 110 | I29: ปริมาณน้ำฝนตรวจวัด | J29: =ROUND(CORREL(Data!$K$2:$K$1827,Data!$C$2:$C$1827),3) -> -0.156
A30: พ.ค. | B30: =ROUND(AVERAGEIFS(Data!$B$2:$B$1827,Data!$F$2:$F$1827,5),2) -> 13.88 | C30: =ROUND(AVERAGEIFS(Data!$C$2:$C$1827,Data!$F$2:$F$1827,5),2) -> 24.18 | D30: =_xlfn.MAXIFS(Data!$C$2:$C$1827,Data!$F$2:$F$1827,5) -> 45
A31: มิ.ย. | B31: =ROUND(AVERAGEIFS(Data!$B$2:$B$1827,Data!$F$2:$F$1827,6),2) -> 14.81 | C31: =ROUND(AVERAGEIFS(Data!$C$2:$C$1827,Data!$F$2:$F$1827,6),2) -> 26.48 | D31: =_xlfn.MAXIFS(Data!$C$2:$C$1827,Data!$F$2:$F$1827,6) -> 55 | I31: ค่าติดลบ = ลม/ฝนมาก → AQI ต่ำลง
A32: ก.ค. | B32: =ROUND(AVERAGEIFS(Data!$B$2:$B$1827,Data!$F$2:$F$1827,7),2) -> 15.67 | C32: =ROUND(AVERAGEIFS(Data!$C$2:$C$1827,Data!$F$2:$F$1827,7),2) -> 28.48 | D32: =_xlfn.MAXIFS(Data!$C$2:$C$1827,Data!$F$2:$F$1827,7) -> 74
A33: ส.ค. | B33: =ROUND(AVERAGEIFS(Data!$B$2:$B$1827,Data!$F$2:$F$1827,8),2) -> 13.85 | C33: =ROUND(AVERAGEIFS(Data!$C$2:$C$1827,Data!$F$2:$F$1827,8),2) -> 24.21 | D33: =_xlfn.MAXIFS(Data!$C$2:$C$1827,Data!$F$2:$F$1827,8) -> 50
A34: ก.ย. | B34: =ROUND(AVERAGEIFS(Data!$B$2:$B$1827,Data!$F$2:$F$1827,9),2) -> 13.56 | C34: =ROUND(AVERAGEIFS(Data!$C$2:$C$1827,Data!$F$2:$F$1827,9),2) -> 24.63 | D34: =_xlfn.MAXIFS(Data!$C$2:$C$1827,Data!$F$2:$F$1827,9) -> 119
A35: ต.ค. | B35: =ROUND(AVERAGEIFS(Data!$B$2:$B$1827,Data!$F$2:$F$1827,10),2) -> 12.16 | C35: =ROUND(AVERAGEIFS(Data!$C$2:$C$1827,Data!$F$2:$F$1827,10),2) -> 21.23 | D35: =_xlfn.MAXIFS(Data!$C$2:$C$1827,Data!$F$2:$F$1827,10) -> 99
A36: พ.ย. | B36: =ROUND(AVERAGEIFS(Data!$B$2:$B$1827,Data!$F$2:$F$1827,11),2) -> 11.37 | C36: =ROUND(AVERAGEIFS(Data!$C$2:$C$1827,Data!$F$2:$F$1827,11),2) -> 19.22 | D36: =_xlfn.MAXIFS(Data!$C$2:$C$1827,Data!$F$2:$F$1827,11) -> 35
A37: ธ.ค. | B37: =ROUND(AVERAGEIFS(Data!$B$2:$B$1827,Data!$F$2:$F$1827,12),2) -> 14.57 | C37: =ROUND(AVERAGEIFS(Data!$C$2:$C$1827,Data!$F$2:$F$1827,12),2) -> 25.6 | D37: =_xlfn.MAXIFS(Data!$C$2:$C$1827,Data!$F$2:$F$1827,12) -> 59
